Workbook

Sheet ห้อง Lab
A1: id | B1: ชื่อภาษาไทย | C1: ชื่อภาษาอังกฤษ | D1: หมายเลขห้อง | E1: ประเภทห้อง Lab | F1: พื้นที่ | G1: ความจุ(คน) | H1: division | I1: unit | J1: ชั้น | K1: id อาคาร | L1: ชื่ออาคาร | M1: sid | N1: responsibility_person | O1: structure | P1: status | Q1: booking | R1: dateadd
A2: 0 | B2: Center Store Room | D2: F9999 | L2: อาคารเครื่องมือ 0
A3: 1 | B3: พื้นที่ปฎิบัติการ SEDA | D3: F01 | E3: พื้นที่ปฎิบัติการ SEDA | F3: 1196.83 | G3: 0 | H3: NULL | I3: NULL | J3: 1 | K3: 1 | L3: =VLOOKUP(K3,อาคาร!$A$2:$B$20,2,FALSE) -> อาคารเครื่องมือ 1 | M3: NULL | N3: NULL | O3: NULL | P3: พร้อมใช้งาน | Q3: NULL | R3: 45737.494
A4: 2 | B4: ห้องปฎิบัติการเครื่องจักรกลพื้นฐาน(โรงเครื่องมือกล... | C4: MACHINE SHOP | D4: F01101 | E4: ห้องปฎิบัติการงานพัฒนาเครื่องมือและสิ่งประดิษฐ์ | F4: 654.93 | G4: 60 | H4: NULL | I4: NULL | J4: 1 | K4: 1 | L4: =VLOOKUP(K4,อาคาร!$A$2:$B$20,2,FALSE) -> อาคารเครื่องมือ 1 | M4: NULL | N4: NULL | O4: NULL | P4: พร้อมใช้งาน | Q4: NULL | R4: 45737.494
A5: 3 | B5: ห้องปฎิบัติการเครื่องกัดโลหะ 5 แกน | C5: CNC MILLING MACHINE 5 AXIS Lab | D5: F01101-5 | E5: พื้นที่ปฎิบัติการต้นแบบทางวิศวกรรม | F5: 26.07 | G5: 6 | H5: NULL | I5: NULL | J5: 1 | K5: 1 | L5: =VLOOKUP(K5,อาคาร!$A$2:$B$20,2,FALSE) -> อาคารเครื่องมือ 1 | M5: NULL | N5: NULL | O5: NULL | P5: พร้อมใช้งาน | Q5: NULL | R5: 45737.494
A6: 4 | B6: ห้องปฎิบัติการเครื่องกลึง CNC | C6: CNC TURNING MACHINE Lab | D6: F01101-8 | E6: ห้องปฎิบัติการงานพัฒนาเครื่องมือและสิ่งประดิษฐ์ | F6: 37.94 | G6: 6 | H6: NULL | I6: NULL | J6: 1 | K6: 1 | L6: =VLOOKUP(K6,อาคาร!$A$2:$B$20,2,FALSE) -> อาคารเครื่องมือ 1 | M6: NULL | N6: NULL | O6: NULL | P6: พร้อมใช้งาน | Q6: NULL | R6: 45737.494
A7: 5 | B7: ห้อง เบิก จ่ายวัสดุอุปกรณ์ งานพัฒนาเครื่องมือและสิ... | C7: Material and equipment disbursement room | D7: F01101-7 | E7: ห้องปฎิบัติการงานพัฒนาเครื่องมือและสิ่งประดิษฐ์ | F7: 33.63 | G7: 4 | H7: NULL | I7: NULL | J7: 1 | K7: 1 | L7: =VLOOKUP(K7,อาคาร!$A$2:$B$20,2,FALSE) -> อาคารเครื่องมือ 1 | M7: NULL | N7: NULL | O7: NULL | P7: พร้อมใช้งาน | Q7: NULL | R7: 45737.494
A8: 6 | B8: ห้องปฎิบัติการ ออกแบบ เขียนแบบ | C8: DESING AND DRAFTING Lab | D8: F01101-6 | E8: ห้องปฎิบัติการงานพัฒนาเครื่องมือและสิ่งประดิษฐ์ | F8: 27.45 | G8: 10 | H8: NULL | I8: NULL | J8: 1 | K8: 1 | L8: =VLOOKUP(K8,อาคาร!$A$2:$B$20,2,FALSE) -> อาคารเครื่องมือ 1 | M8: NULL | N8: NULL | O8: NULL | P8: พร้อมใช้งาน | Q8: NULL | R8: 45737.494
A9: 7 | B9: ห้องเก็บวัสดุงานพัฒนาเครื่องมือและสิ่งประดิษฐ์ | D9: F01101-3 | E9: ห้องปฎิบัติการงานพัฒนาเครื่องมือและสิ่งประดิษฐ์ | F9: 11.39 | G9: 1 | H9: NULL | I9: NULL | J9: 1 | K9: 1 | L9: =VLOOKUP(K9,อาคาร!$A$2:$B$20,2,FALSE) -> อาคารเครื่องมือ 1 | M9: NULL | N9: NULL | O9: NULL | P9: พร้อมใช้งาน | Q9: NULL | R9: 45737.494
A10: 8 | B10: ห้องปฎิบัติการเครื่องมือวัด | C10: MEASURING TOOLS Lab | D10: F01101-4 | E10: ห้องปฎิบัติการงานพัฒนาเครื่องมือและสิ่งประดิษฐ์ | F10: 33 | G10: 4 | H10: NULL | I10: NULL | J10: 1 | K10: 1 | L10: =VLOOKUP(K10,อาคาร!$A$2:$B$20,2,FALSE) -> อาคารเครื่องมือ 1 | M10: NULL | N10: NULL | O10: NULL | P10: พร้อมใช้งาน | Q10: NULL | R10: 45737.494
A11: 9 | B11: ห้องพักพนักงาน งานพัฒนาเครื่องมือและสิ่งประดิษฐ์ | C11: STAFF ROOM | D11: F01101-2 | E11: ห้องปฎิบัติการงานพัฒนาเครื่องมือและสิ่งประดิษฐ์ | F11: 22.84 | G11: 4 | H11: NULL | I11: NULL | J11: 1 | K11: 1 | L11: =VLOOKUP(K11,อาคาร!$A$2:$B$20,2,FALSE) -> อาคารเครื่องมือ 1 | M11: NULL | N11: NULL | O11: NULL | P11: พร้อมใช้งาน | Q11: NULL | R11: 45737.494
A12: 10 | B12: ห้องปฎิบัติการเครื่องกัดโลหะ 3 แกน | C12: CNC MILLING 3 AXIS Lab | D12: F01101-1 | E12: ห้องปฎิบัติการงานพัฒนาเครื่องมือและสิ่งประดิษฐ์ | F12: 22.75 | G12: 6 | H12: NULL | I12: NULL | J12: 1 | K12: 1 | L12: =VLOOKUP(K12,อาคาร!$A$2:$B$20,2,FALSE) -> อาคารเครื่องมือ 1 | M12: NULL | N12: NULL | O12: NULL | P12: พร้อมใช้งาน | Q12: NULL | R12: 45737.494
A13: 11 | B13: ห้องระบบไฟฟ้าสำรองประจำอาคาร | D13: F01101-12 | E13: ห้องปฎิบัติการงานพัฒนาเครื่องมือและสิ่งประดิษฐ์ | F13: 29.79 | G13: 4 | H13: NULL | I13: NULL | J13: 1 | K13: 1 | L13: =VLOOKUP(K13,อาคาร!$A$2:$B$20,2,FALSE) -> อาคารเครื่องมือ 1 | M13: NULL | N13: NULL | O13: NULL | P13: พร้อมใช้งาน | Q13: NULL | R13: 45737.494
A14: 12 | B14: ห้องปฎิบัติการเครื่องตัดววัสดุด้วยแสงเลเซอร์ CNC | C14: CNC LASER CUTTING MACHINE Lab | D14: F01101-9 | E14: ห้องปฎิบัติการงานพัฒนาเครื่องมือและสิ่งประดิษฐ์ | F14: 49.44 | G14: 6 | H14: NULL | I14: NULL | J14: 1 | K14: 1 | L14: =VLOOKUP(K14,อาคาร!$A$2:$B$20,2,FALSE) -> อาคารเครื่องมือ 1 | M14: NULL | N14: NULL | O14: NULL | P14: พร้อมใช้งาน | Q14: NULL | R14: 45737.494
A15: 13 | B15: ห้องปฎิบัติการ งานพ่นสี | C15: PAINT BOOTH | D15: F01101-10 | E15: ห้องปฎิบัติการงานพัฒนาเครื่องมือและสิ่งประดิษฐ์ | F15: 20.36 | G15: 4 | H15: NULL | I15: NULL | J15: 1 | K15: 1 | L15: =VLOOKUP(K15,อาคาร!$A$2:$B$20,2,FALSE) -> อาคารเครื่องมือ 1 | M15: NULL | N15: NULL | O15: NULL | P15: พร้อมใช้งาน | Q15: NULL | R15: 45737.494
A16: 14 | B16: ห้องควบคุมระบบไฟฟ้าประจำอาคาร | C16: Electrical system control room for the building | D16: F01101-11 | E16: ห้องปฎิบัติการงานพัฒนาเครื่องมือและสิ่งประดิษฐ์ | F16: 25.91 | G16: 0 | H16: NULL | I16: NULL | J16: 1 | K16: 1 | L16: =VLOOKUP(K16,อาคาร!$A$2:$B$20,2,FALSE) -> อาคารเครื่องมือ 1 | M16: NULL | N16: NULL | O16: NULL | P16: พร้อมใช้งาน | Q16: NULL | R16: 45737.494
A17: 15 | B17: ห้องปฎิบัติการวิศวกรรมการผลิต | C17: RAPID PROTOTYPE Lab | D17: F01115A | E17: ห้องปฎิบัติการวิศวกรรมการผลิต | F17: 62.31 | G17: 20 | H17: NULL | I17: NULL | J17: 1 | K17: 1 | L17: =VLOOKUP(K17,อาคาร!$A$2:$B$20,2,FALSE) -> อาคารเครื่องมือ 1 | M17: NULL | N17: NULL | O17: NULL | P17: พร้อมใช้งาน | Q17: NULL | R17: 45737.494
A18: 16 | B18: ห้องปฎิบัติการวิศวกรรมการผลิต Seminar 1 | C18: Seminar 1 | D18: F01110A | E18: ห้องปฎิบัติการวิศวกรรมการผลิต | F18: 115.3 | G18: 60 | H18: NULL | I18: NULL | J18: 1 | K18: 1 | L18: =VLOOKUP(K18,อาคาร!$A$2:$B$20,2,FALSE) -> อาคารเครื่องมือ 1 | M18: NULL | N18: NULL | O18: NULL | P18: พร้อมใช้งาน | Q18: NULL | R18: 45737.494
A19: 17 | B19: ห้องปฎิบัติการทดสอบวัสดุก่อสร้าง | C19: Construction Materials Testing Laboratory | D19: F01102I | E19: ห้องปฎิบัติการทดสอบวัสดุก่อสร้าง Construction Mate... | F19: 15.4 | G19: 2 | H19: NULL | I19: NULL | J19: 1 | K19: 1 | L19: =VLOOKUP(K19,อาคาร!$A$2:$B$20,2,FALSE) -> อาคารเครื่องมือ 1 | M19: NULL | N19: NULL | O19: NULL | P19: พร้อมใช้งาน | Q19: NULL | R19: 45737.494
A20: 18 | B20: ห้องปฎิบัติการทดสอบวัสดุก่อสร้าง | C20: Construction Materials Testing Laboratory | D20: F01102E | E20: ห้องปฎิบัติการทดสอบวัสดุก่อสร้าง Construction Mate... | F20: 134.8 | G20: 8 | H20: NULL | I20: NULL | J20: 1 | K20: 1 | L20: =VLOOKUP(K20,อาคาร!$A$2:$B$20,2,FALSE) -> อาคารเครื่องมือ 1 | M20: NULL | N20: NULL | O20: NULL | P20: พร้อมใช้งาน | Q20: NULL | R20: 45737.494
A21: 19 | B21: ห้องปฎิบัติการทดสอบวัสดุก่อสร้าง | C21: Construction Materials Testing Laboratory | D21: F01102D | E21: ห้องปฎิบัติการทดสอบวัสดุก่อสร้าง Construction Mate... | F21: 17.6 | G21: 6 | H21: NULL | I21: NULL | J21: 1 | K21: 1 | L21: =VLOOKUP(K21,อาคาร!$A$2:$B$20,2,FALSE) -> อาคารเครื่องมือ 1 | M21: NULL | N21: NULL | O21: NULL | P21: พร้อมใช้งาน | Q21: NULL | R21: 45737.494
A22: 20 | B22: ห้องปฎิบัติการทดสอบวัสดุก่อสร้าง | C22: Construction Materials Testing Laboratory | D22: F01102K | E22: ห้องปฎิบัติการทดสอบวัสดุก่อสร้าง Construction Mate... | F22: 24.01 | G22: 4 | H22: NULL | I22: NULL | J22: 1 | K22: 1 | L22: =VLOOKUP(K22,อาคาร!$A$2:$B$20,2,FALSE) -> อาคารเครื่องมือ 1 | M22: NULL | N22: NULL | O22: NULL | P22: พร้อมใช้งาน | Q22: NULL | R22: 45737.494
A23: 21 | B23: ห้องปฎิบัติการทดสอบวัสดุก่อสร้าง | C23: Construction Materials Testing Laboratory | D23: F01102B | E23: ห้องปฎิบัติการทดสอบวัสดุก่อสร้าง Construction Mate... | F23: 41.2 | G23: 4 | H23: NULL | I23: NULL | J23: 1 | K23: 1 | L23: =VLOOKUP(K23,อาคาร!$A$2:$B$20,2,FALSE) -> อาคารเครื่องมือ 1 | M23: NULL | N23: NULL | O23: NULL | P23: พร้อมใช้งาน | Q23: NULL | R23: 45737.494
A24: 22 | B24: ห้องปฎิบัติการทดสอบวัสดุก่อสร้าง | C24: Construction Materials Testing Laboratory | D24: F01102A | E24: ห้องปฎิบัติการทดสอบวัสดุก่อสร้าง Construction Mate... | F24: 17.54 | G24: 4 | H24: NULL | I24: NULL | J24: 1 | K24: 1 | L24: =VLOOKUP(K24,อาคาร!$A$2:$B$20,2,FALSE) -> อาคารเครื่องมือ 1 | M24: NULL | N24: NULL | O24: NULL | P24: พร้อมใช้งาน | Q24: NULL | R24: 45737.494
A25: 23 | B25: ห้องปฎิบัติการทดสอบวัสดุก่อสร้าง | C25: Construction Materials Testing Laboratory | D25: F01102C | E25: ห้องปฎิบัติการทดสอบวัสดุก่อสร้าง Construction Mate... | F25: 58.22 | G25: 8 | H25: NULL | I25: NULL | J25: 1 | K25: 1 | L25: =VLOOKUP(K25,อาคาร!$A$2:$B$20,2,FALSE) -> อาคารเครื่องมือ 1 | M25: NULL | N25: NULL | O25: NULL | P25: พร้อมใช้งาน | Q25: NULL | R25: 45737.494
... A40: 38 | B40: ห้องปฎิบัติการทดสอบวัสดุก่อสร้าง | C40: Construction Materials Testing Laboratory | D40: F01105B | E40: ห้องปฎิบัติการทดสอบวัสดุก่อสร้าง Construction Mate... | F40: 6.5 | G40: 1 | H40: NULL | I40: NULL | J40: 1 | K40: 1 | L40: =VLOOKUP(K40,อาคาร!$A$2:$B$20,2,FALSE) -> อาคารเครื่องมือ 1 | M40: NULL | N40: NULL | O40: NULL | P40: พร้อมใช้งาน | Q40: NULL | R40: 45737.494
A41: 44 | B41: ห้องเก็บอุปกรณ์ปฏิบัติการ สโตร์ | D41: F01111A | E41: ห้องปฎิบัติการวิศวกรรมการผลิต | F41: 49 | G41: 0 | H41: NULL | I41: NULL | J41: 1 | K41: 1 | L41: =VLOOKUP(K41,อาคาร!$A$2:$B$20,2,FALSE) -> อาคารเครื่องมือ 1 | M41: NULL | N41: NULL | O41: NULL | P41: พร้อมใช้งาน | Q41: NULL | R41: 45737.494
A42: 45 | B42: ห้องควบคุมไฟฟ้า | D42: F01112A | E42: ห้องปฎิบัติการวิศวกรรมการผลิต | F42: 13.84 | G42: 0 | H42: NULL | I42: NULL | J42: 1 | K42: 1 | L42: =VLOOKUP(K42,อาคาร!$A$2:$B$20,2,FALSE) -> อาคารเครื่องมือ 1 | M42: NULL | N42: NULL | O42: NULL | P42: พร้อมใช้งาน | Q42: NULL | R42: 45737.494
A43: 46 | B43: ห้องปฎิบัติการเครื่องมือวัดละเอียด 3 มิติ | C43: 3D SCANNER Lab | D43: F01113A | E43: ห้องปฎิบัติการวิศวกรรมการผลิต | F43: 15.81 | G43: 10 | H43: NULL | I43: NULL | J43: 1 | K43: 1 | L43: =VLOOKUP(K43,อาคาร!$A$2:$B$20,2,FALSE) -> อาคารเครื่องมือ 1 | M43: NULL | N43: NULL | O43: NULL | P43: พร้อมใช้งาน | Q43: NULL | R43: 45737.494
A44: 47 | B44: ห้องพักเจ้าหน้าที่ประจำปฎิบัติการวิศวกรรมการผลิต | D44: F01114A | E44: ห้องปฎิบัติการวิศวกรรมการผลิต | F44: 15.18 | G44: 1 | H44: NULL | I44: NULL | J44: 1 | K44: 1 | L44: =VLOOKUP(K44,อาคาร!$A$2:$B$20,2,FALSE) -> อาคารเครื่องมือ 1 | M44: NULL | N44: NULL | O44: NULL | P44: พร้อมใช้งาน | Q44: NULL | R44: 45737.494
A45: 48 | B45: ห้องปฎิบัติการวิศวกรรมการผลิต Seminar2 | C45: Seminar2 | D45: F01116A | E45: ห้องปฎิบัติการวิศวกรรมการผลิต | F45: 93.91 | G45: 30 | H45: NULL | I45: NULL | J45: 1 | K45: 1 | L45: =VLOOKUP(K45,อาคาร!$A$2:$B$20,2,FALSE) -> อาคารเครื่องมือ 1 | M45: NULL | N45: NULL | O45: NULL | P45: พร้อมใช้งาน | Q45: NULL | R45: 45737.494
A46: 51 | B46: ห้องปฎิบัติการวิศวกรรมการผลิต Seminar3 | C46: Seminar3 | D46: F01118A | E46: ห้องปฎิบัติการวิศวกรรมการผลิต | F46: 82.81 | G46: 40 | H46: NULL | I46: NULL | J46: 1 | K46: 1 | L46: =VLOOKUP(K46,อาคาร!$A$2:$B$20,2,FALSE) -> อาคารเครื่องมือ 1 | M46: NULL | N46: NULL | O46: NULL | P46: พร้อมใช้งาน | Q46: NULL | R46: 45737.494
A47: 52 | B47: ห้องปฎิบัติการหุ่นยนต์เชื่อมอุตสาหกรรม | C47: WELDING ROBOT CNC Lab | D47: F01119A | E47: ห้องปฎิบัติการวิศวกรรมการผลิต | F47: 121.63 | G47: 20 | H47: NULL | I47: NULL | J47: 1 | K47: 1 | L47: =VLOOKUP(K47,อาคาร!$A$2:$B$20,2,FALSE) -> อาคารเครื่องมือ 1 | M47: NULL | N47: NULL | O47: NULL | P47: พร้อมใช้งาน | Q47: NULL | R47: 45737.494
A48: 53 | B48: ห้องปฎิบัติการโรงงานอุตสาหกรรม 4.0 | C48: FACTORY 4.0 Lab | D48: F01117A | E48: ห้องปฎิบัติการวิศวกรรมการผลิต | F48: 123.82 | G48: 30 | H48: NULL | I48: NULL | J48: 1 | K48: 1 | L48: =VLOOKUP(K48,อาคาร!$A$2:$B$20,2,FALSE) -> อาคารเครื่องมือ 1 | M48: NULL | N48: NULL | O48: NULL | P48: พร้อมใช้งาน | Q48: NULL | R48: 45737.494
A49: 58 | B49: ห้องปฎิบัติการกัดกลึงอัตโนมัติขนาดเล็ก | C49: MINI CNC Lab | D49: F01122A | E49: ห้องปฎิบัติการวิศวกรรมการผลิต | F49: 20.52 | G49: 10 | H49: NULL | I49: NULL | J49: 1 | K49: 1 | L49: =VLOOKUP(K49,อาคาร!$A$2:$B$20,2,FALSE) -> อาคารเครื่องมือ 1 | M49: NULL | N49: NULL | O49: NULL | P49: พร้อมใช้งาน | Q49: NULL | R49: 45737.494
A50: 59 | B50: ห้องปฎิบัติการตัดชิ้นงานด้วยเลเซอร์ | C50: LASER CUT Lab | D50: F01122B | E50: ห้องปฎิบัติการวิศวกรรมการผลิต | F50: 30.14 | G50: 10 | H50: NULL | I50: NULL | J50: 1 | K50: 1 | L50: =VLOOKUP(K50,อาคาร!$A$2:$B$20,2,FALSE) -> อาคารเครื่องมือ 1 | M50: NULL | N50: NULL | O50: NULL | P50: พร้อมใช้งาน | Q50: NULL | R50: 45737.494
A51: 60 | B51: ห้องปฎิบัติการตัดพับบรรจุภัณฑ์ | C51: PACKAGING STICKKER Lab | D51: F01121A | E51: ห้องปฎิบัติการวิศวกรรมการผลิต | F51: 51.04 | G51: 10 | H51: NULL | I51: NULL | J51: 1 | K51: 1 | L51: =VLOOKUP(K51,อาคาร!$A$2:$B$20,2,FALSE) -> อาคารเครื่องมือ 1 | M51: NULL | N51: NULL | O51: NULL | P51: พร้อมใช้งาน | Q51: NULL | R51: 45737.494
A52: 61 | B52: ห้องปฎิบัติการวิศวกรรมเคมี | C52: ห้องปฎิบัติการวิศวกรรมเคมี | D52: F01124A | E52: ห้องปฎิบัติการวิศวกรรมเคมี | F52: 16.1 | G52: 6 | H52: NULL | I52: NULL | J52: 1 | K52: 1 | L52: =VLOOKUP(K52,อาคาร!$A$2:$B$20,2,FALSE) -> อาคารเครื่องมือ 1 | M52: NULL | N52: NULL | O52: NULL | P52: พร้อมใช้งาน | Q52: NULL | R52: 45737.494
A53: 62 | B53: ห้องปฎิบัติการวิศวกรรมเคมี | C53: ห้องปฎิบัติการวิศวกรรมเคมี | D53: F01125A | E53: ห้องปฎิบัติการวิศวกรรมเคมี | F53: 14.43 | G53: 6 | H53: NULL | I53: NULL | J53: 1 | K53: 1 | L53: =VLOOKUP(K53,อาคาร!$A$2:$B$20,2,FALSE) -> อาคารเครื่องมือ 1 | M53: NULL | N53: NULL | O53: NULL | P53: พร้อมใช้งาน | Q53: NULL | R53: 45737.494
A54: 63 | B54: ห้องปฎิบัติการวิศวกรรมเคมี | C54: ห้องปฎิบัติการวิศวกรรมเคมี | D54: F01126A | E54: ห้องปฎิบัติการวิศวกรรมเคมี | F54: 22.99 | G54: 6 | H54: NULL | I54: NULL | J54: 1 | K54: 1 | L54: =VLOOKUP(K54,อาคาร!$A$2:$B$20,2,FALSE) -> อาคารเครื่องมือ 1 | M54: NULL | N54: NULL | O54: NULL | P54: พร้อมใช้งาน | Q54: NULL | R54: 45737.494
...

Sheet อาคาร
A1: id | B1: name_th | C1: name_eng | D1: shortname | E1: utilizing_area | F1: no_of_foor | G1: no_of_room | H1: location | I1: sketch
A2: 1 | B2: อาคารเครื่องมือ 1 | C2: Facility Building 1 | D2: F1 | E2: 7767 | F2: 3 | G2: 0 | H2: 14.878059,102.017521 | I2: -
A3: 2 | B3: อาคารเครื่องมือ 2 | C3: Facility Building 2 | D3: F2 | E3: 8576 | F3: 2 | G3: 0 | H3: 14.877135,102.018145 | I3: -
A4: 3 | B4: อาคารเครื่องมือ 3 | C4: Facility Building 3 | D4: F3 | E4: 9984 | F4: 2 | G4: 0 | H4: 14.876226,102.018767 | I4: -
A5: 4 | B5: อาคารเครื่องมือ 4 | C5: Facility Building 4 | D5: F4 | E5: 7128 | F5: 2 | G5: 0 | H5: 14.877238,102.016324 | I5: -
A6: 5 | B6: อาคารเครื่องมือ 5 | C6: Facility Building 5 | D6: F5 | E6: 7104 | F6: 2 | G6: 0 | H6: 14.876351,102.016935 | I6: -
A7: 6 | B7: อาคารเครื่องมือ 6 | C7: Facility Building 6 | D7: F6 | E7: 8204 | F7: 2 | G7: 0 | H7: 14.875401,102.017595 | I7: -
A8: 7 | B8: อาคารเครื่องมือ 7 | C8: Facility Building 7 | D8: F7 | E8: 3820 | F8: 2 | G8: 0 | H8: 14.875052,102.020983 | I8: -
A9: 9 | B9: อาคารเฉลิมพระเกียรติ 72 พรรษา (อาคารเครื่องมือ9) | C9: Facility Building 9 | D9: F9 | E9: 24624 | F9: 3 | G9: 0 | H9: 14.874642,102.016481 | I9: -
A10: 10 | B10: อาคารเครื่องมือ 10 | C10: Facility Building 10 | D10: F10 | E10: 10560 | F10: 3 | G10: 0 | H10: 14.876541,102.015179 | I10: -
A11: 11 | B11: อาคารคลังสารเคมี | C11: Chemical Storage | D11: คลังสารเคมี | E11: 0 | F11: 1 | G11: 0 | H11: 14.878127,102.017947 | I11: -
A12: 12 | B12: อาคารเครื่องมือ 6/1 | C12: Facility Building 6/1 | D12: F6/1 | E12: 800 | F12: 2 | G12: 0 | H12: 14.875581,102.017079 | I12: -
A13: 14 | B13: อาคารสัตว์ทดลอง | C13: 320F | D13: สัตว์ทดลอง | E13: 0 | F13: 1 | G13: 0 | H13: 14.875542,102.008685 | I13: -
... A20: 22 | B20: อาคารเครื่องมือ 16 | C20: Facility Building 16 | D20: F16 | E20: 0 | F20: 3 | G20: 0 | H20: 14.875288, 102.015005 | I20: -
A21: 23 | B21: อาคารเครื่องมือ 0 | D21: F0
